test_login.py::FrontEndHomePageTest::test_login_R2_1_1
--------------------------------------------------------------------
Last Page: data:,
  Browser: chrome
Timestamp: 1636195113  (Unix Timestamp)
     Date: Saturday, November 6, 2021
     Time: 6:38:33 AM  (Eastern Daylight Time, UTC-05:00)
--------------------------------------------------------------------
Traceback: File "C:\Users\Wilson\AppData\Local\Programs\Python\Python39\lib\unittest\case.py", line 593, in run
    self._callTestMethod(testMethod)
  File "C:\Users\Wilson\AppData\Local\Programs\Python\Python39\lib\unittest\case.py", line 550, in _callTestMethod
    method()
  File "C:\Users\Wilson\CISC327\qbay_test\frontend\test_login.py", line 18, in test_login_R2_1_1
    testing_register("R2_1_1", "R2_1_1@test.com", "Test123$")
  File "C:\Users\Wilson\CISC327\qbay\models.py", line 165, in testing_register
    db.session.commit()
  File "<string>", line 2, in commit
  File "C:\Users\Wilson\AppData\Roaming\Python\Python39\site-packages\sqlalchemy\orm\session.py", line 1428, in commit
    self._transaction.commit(_to_root=self.future)
  File "C:\Users\Wilson\AppData\Roaming\Python\Python39\site-packages\sqlalchemy\orm\session.py", line 829, in commit
    self._prepare_impl()
  File "C:\Users\Wilson\AppData\Roaming\Python\Python39\site-packages\sqlalchemy\orm\session.py", line 808, in _prepare_impl
    self.session.flush()
  File "C:\Users\Wilson\AppData\Roaming\Python\Python39\site-packages\sqlalchemy\orm\session.py", line 3298, in flush
    self._flush(objects)
  File "C:\Users\Wilson\AppData\Roaming\Python\Python39\site-packages\sqlalchemy\orm\session.py", line 3438, in _flush
    transaction.rollback(_capture_exception=True)
  File "C:\Users\Wilson\AppData\Roaming\Python\Python39\site-packages\sqlalchemy\util\langhelpers.py", line 70, in __exit__
    compat.raise_(
  File "C:\Users\Wilson\AppData\Roaming\Python\Python39\site-packages\sqlalchemy\util\compat.py", line 207, in raise_
    raise exception
  File "C:\Users\Wilson\AppData\Roaming\Python\Python39\site-packages\sqlalchemy\orm\session.py", line 3398, in _flush
    flush_context.execute()
  File "C:\Users\Wilson\AppData\Roaming\Python\Python39\site-packages\sqlalchemy\orm\unitofwork.py", line 456, in execute
    rec.execute(self)
  File "C:\Users\Wilson\AppData\Roaming\Python\Python39\site-packages\sqlalchemy\orm\unitofwork.py", line 630, in execute
    util.preloaded.orm_persistence.save_obj(
  File "C:\Users\Wilson\AppData\Roaming\Python\Python39\site-packages\sqlalchemy\orm\persistence.py", line 242, in save_obj
    _emit_insert_statements(
  File "C:\Users\Wilson\AppData\Roaming\Python\Python39\site-packages\sqlalchemy\orm\persistence.py", line 1219, in _emit_insert_statements
    result = connection._execute_20(
  File "C:\Users\Wilson\AppData\Roaming\Python\Python39\site-packages\sqlalchemy\engine\base.py", line 1582, in _execute_20
    return meth(self, args_10style, kwargs_10style, execution_options)
  File "C:\Users\Wilson\AppData\Roaming\Python\Python39\site-packages\sqlalchemy\sql\elements.py", line 324, in _execute_on_connection
    return connection._execute_clauseelement(
  File "C:\Users\Wilson\AppData\Roaming\Python\Python39\site-packages\sqlalchemy\engine\base.py", line 1451, in _execute_clauseelement
    ret = self._execute_context(
  File "C:\Users\Wilson\AppData\Roaming\Python\Python39\site-packages\sqlalchemy\engine\base.py", line 1813, in _execute_context
    self._handle_dbapi_exception(
  File "C:\Users\Wilson\AppData\Roaming\Python\Python39\site-packages\sqlalchemy\engine\base.py", line 1994, in _handle_dbapi_exception
    util.raise_(
  File "C:\Users\Wilson\AppData\Roaming\Python\Python39\site-packages\sqlalchemy\util\compat.py", line 207, in raise_
    raise exception
  File "C:\Users\Wilson\AppData\Roaming\Python\Python39\site-packages\sqlalchemy\engine\base.py", line 1770, in _execute_context
    self.dialect.do_execute(
  File "C:\Users\Wilson\AppData\Roaming\Python\Python39\site-packages\sqlalchemy\engine\default.py", line 717, in do_execute
    cursor.execute(statement, parameters)
Exception: (sqlite3.IntegrityError) UNIQUE constraint failed: user.username
[SQL: INSERT INTO user (email, username, password, balance, shipping_address, postal_code) VALUES (?, ?, ?, ?, ?, ?)]
[parameters: ('R2_1_1@test.com', 'R2_1_1', 'Test123$', 100.0, '', '')]
(Background on this error at: http://sqlalche.me/e/14/gkpj)